<?xml version="1.0" encoding="utf-8"?>
<!-- This URDF was automatically created by SolidWorks to URDF Exporter! Originally created by Stephen Brawner (brawner@gmail.com) 
     Commit Version: 1.5.1-0-g916b5db  Build Version: 1.5.7152.31018
     For more information, please see http://wiki.ros.org/sw_urdf_exporter -->
<robot
  name="gsat_urdf">
  <link
    name="base_link">
    <inertial>
      <origin
        xyz="0.266854048300906 -0.0196745688344671 0.181448480588276"
        rpy="0 0 0" />
      <mass
        value="10.6288067599575" />
      <inertia
        ixx="0.114951087561527"
        ixy="0.00764206728612218"
        ixz="-0.053312933184893"
        iyy="0.225745931152675"
        iyz="-0.000337447770241439"
        izz="0.31011873472109" />
    </inertial>
    <visual>
      <origin
        xyz="0 0 0"
        rpy="0 0 0" />
      <geometry>
        <mesh
          filename="package://gsat_urdf/meshes/base_link.STL" />
      </geometry>
      <material
        name="">
        <color
          rgba="0.792156862745098 0.819607843137255 0.933333333333333 1" />
      </material>
    </visual>
    <collision>
      <origin
        xyz="0 0 0"
        rpy="0 0 0" />
      <geometry>
        <mesh
          filename="package://gsat_urdf/meshes/base_link.STL" />
      </geometry>
    </collision>
  </link>
  <link
    name="LF">
    <inertial>
      <origin
        xyz="0.0819570172204619 -0.00667616801088727 0.0692419076642504"
        rpy="0 0 0" />
      <mass
        value="0.792785300978338" />
      <inertia
        ixx="0.000649876873137279"
        ixy="9.17115065194579E-05"
        ixz="-4.62319815270522E-14"
        iyy="0.00176830170477571"
        iyz="-1.60623698044517E-13"
        izz="0.00238763773202939" />
    </inertial>
    <visual>
      <origin
        xyz="0 0 0"
        rpy="0 0 0" />
      <geometry>
        <mesh
          filename="package://gsat_urdf/meshes/LF.STL" />
      </geometry>
      <material
        name="">
        <color
          rgba="0.792156862745098 0.819607843137255 0.933333333333333 1" />
      </material>
    </visual>
    <collision>
      <origin
        xyz="0 0 0"
        rpy="0 0 0" />
      <geometry>
        <mesh
          filename="package://gsat_urdf/meshes/LF.STL" />
      </geometry>
    </collision>
  </link>
  <joint
    name="LFJ"
    type="continuous">
    <origin
      xyz="0.54403 -0.19894 0.1742"
      rpy="0.019508 0.059775 -0.30358" />
    <parent
      link="base_link" />
    <child
      link="LF" />
    <axis
      xyz="0 0 1" />
  </joint>
  <link
    name="LB">
    <inertial>
      <origin
        xyz="-7.90398302363826E-12 -1.54344805686213E-09 -0.0349837038047943"
        rpy="0 0 0" />
      <mass
        value="0.205470115797593" />
      <inertia
        ixx="0.000165642318603424"
        ixy="-1.01480732928798E-11"
        ixz="-1.3869159218706E-12"
        iyy="0.000165642302126842"
        iyz="6.74308408623334E-13"
        izz="0.000321571008345194" />
    </inertial>
    <visual>
      <origin
        xyz="0 0 0"
        rpy="0 0 0" />
      <geometry>
        <mesh
          filename="package://gsat_urdf/meshes/LB.STL" />
      </geometry>
      <material
        name="">
        <color
          rgba="0.792156862745098 0.819607843137255 0.933333333333333 1" />
      </material>
    </visual>
    <collision>
      <origin
        xyz="0 0 0"
        rpy="0 0 0" />
      <geometry>
        <mesh
          filename="package://gsat_urdf/meshes/LB.STL" />
      </geometry>
    </collision>
  </link>
  <joint
    name="LBJ"
    type="continuous">
    <origin
      xyz="0.059932 -0.075302 0.18823"
      rpy="-3.1321 0.062158 -0.46801" />
    <parent
      link="base_link" />
    <child
      link="LB" />
    <axis
      xyz="0 0 1" />
  </joint>
  <link
    name="RB">
    <inertial>
      <origin
        xyz="-6.81596043494714E-10 -1.38181031200668E-09 0.0374137646332866"
        rpy="0 0 0" />
      <mass
        value="0.205470112335451" />
      <inertia
        ixx="0.0001656423233608"
        ixy="-6.81374058466699E-13"
        ixz="-1.60661475502206E-12"
        iyy="0.00016564229715823"
        iyz="1.42086575117368E-14"
        izz="0.000321571008307375" />
    </inertial>
    <visual>
      <origin
        xyz="0 0 0"
        rpy="0 0 0" />
      <geometry>
        <mesh
          filename="package://gsat_urdf/meshes/RB.STL" />
      </geometry>
      <material
        name="">
        <color
          rgba="0.792156862745098 0.819607843137255 0.933333333333333 1" />
      </material>
    </visual>
    <collision>
      <origin
        xyz="0 0 0"
        rpy="0 0 0" />
      <geometry>
        <mesh
          filename="package://gsat_urdf/meshes/RB.STL" />
      </geometry>
    </collision>
  </link>
  <joint
    name="RBJ"
    type="continuous">
    <origin
      xyz="0.040237 -0.061264 -0.19593"
      rpy="-3.1345 -0.062471 2.4089" />
    <parent
      link="base_link" />
    <child
      link="RB" />
    <axis
      xyz="0 0 1" />
  </joint>
  <link
    name="RF">
    <inertial>
      <origin
        xyz="0.0664619402598657 -0.0484183289259268 -0.0818819864444948"
        rpy="0 0 0" />
      <mass
        value="0.792785300978338" />
      <inertia
        ixx="0.00103535947125629"
        ixy="0.000539395500315438"
        ixz="-1.44615893424901E-13"
        iyy="0.0013828191066567"
        iyz="8.06322104354371E-14"
        izz="0.00238763773202939" />
    </inertial>
    <visual>
      <origin
        xyz="0 0 0"
        rpy="0 0 0" />
      <geometry>
        <mesh
          filename="package://gsat_urdf/meshes/RF.STL" />
      </geometry>
      <material
        name="">
        <color
          rgba="0.792156862745098 0.819607843137255 0.933333333333333 1" />
      </material>
    </visual>
    <collision>
      <origin
        xyz="0 0 0"
        rpy="0 0 0" />
      <geometry>
        <mesh
          filename="package://gsat_urdf/meshes/RF.STL" />
      </geometry>
    </collision>
  </link>
  <joint
    name="RFJ"
    type="continuous">
    <origin
      xyz="0.52334 -0.1842 -0.22925"
      rpy="0.050393 0.037616 0.31084" />
    <parent
      link="base_link" />
    <child
      link="RF" />
    <axis
      xyz="0 0 1" />
  </joint>
</robot>